Workbook

Sheet 全部
A1: 序号 | B1: 学校名称 | C1: 主管部门 | D1: 省份 | E1: 城市 | F1: 985 | G1: 211 | H1: 双一流 | I1: 类型 | J1: 层次 | K1: 性质
A2: 1 | B2: 北京大学 | C2: =VLOOKUP(B2,教育部大学名单!$B$1:$D$2920,3,FALSE) -> 教育部 | D2: 北京 | E2: 北京 | F2: =IFERROR(VLOOKUP(B2,'985'!$B$2:$D$40,3,FALSE),"") -> 985 | G2: =IFERROR(VLOOKUP(B2,'211'!$B$2:$D$116,3,FALSE),"") -> 211 | H2: =IFERROR(VLOOKUP(B2,双一流!$B$2:$D$148,3,FALSE),"") -> 双一流 | I2: =IFERROR(VLOOKUP(B2,汇总!$B$2:$I$2921,8,FALSE),"") -> 综合 | J2: 本科 | K2: 公办
A3: 2 | B3: 中国人民大学 | C3: =VLOOKUP(B3,教育部大学名单!$B$1:$D$2920,3,FALSE) -> 教育部 | D3: 北京 | E3: 北京 | F3: =IFERROR(VLOOKUP(B3,'985'!$B$2:$D$40,3,FALSE),"") -> 985 | G3: =IFERROR(VLOOKUP(B3,'211'!$B$2:$D$116,3,FALSE),"") -> 211 | H3: =IFERROR(VLOOKUP(B3,双一流!$B$2:$D$148,3,FALSE),"") -> 双一流 | I3: =IFERROR(VLOOKUP(B3,汇总!$B$2:$I$2921,8,FALSE),"") -> 综合 | J3: 本科 | K3: 公办
A4: 3 | B4: 清华大学 | C4: =VLOOKUP(B4,教育部大学名单!$B$1:$D$2920,3,FALSE) -> 教育部 | D4: 北京 | E4: 北京 | F4: =IFERROR(VLOOKUP(B4,'985'!$B$2:$D$40,3,FALSE),"") -> 985 | G4: =IFERROR(VLOOKUP(B4,'211'!$B$2:$D$116,3,FALSE),"") -> 211 | H4: =IFERROR(VLOOKUP(B4,双一流!$B$2:$D$148,3,FALSE),"") -> 双一流 | I4: =IFERROR(VLOOKUP(B4,汇总!$B$2:$I$2921,8,FALSE),"") -> 综合 | J4: 本科 | K4: 公办
A5: 4 | B5: 北京交通大学 | C5: =VLOOKUP(B5,教育部大学名单!$B$1:$D$2920,3,FALSE) -> 教育部 | D5: 北京 | E5: 北京 | F5: =IFERROR(VLOOKUP(B5,'985'!$B$2:$D$40,3,FALSE),"") | G5: =IFERROR(VLOOKUP(B5,'211'!$B$2:$D$116,3,FALSE),"") -> 211 | H5: =IFERROR(VLOOKUP(B5,双一流!$B$2:$D$148,3,FALSE),"") -> 双一流 | I5: =IFERROR(VLOOKUP(B5,汇总!$B$2:$I$2921,8,FALSE),"") -> 理工 | J5: 本科 | K5: 公办
A6: 5 | B6: 北京工业大学 | C6: =VLOOKUP(B6,教育部大学名单!$B$1:$D$2920,3,FALSE) -> 北京市 | D6: 北京 | E6: 北京 | F6: =IFERROR(VLOOKUP(B6,'985'!$B$2:$D$40,3,FALSE),"") | G6: =IFERROR(VLOOKUP(B6,'211'!$B$2:$D$116,3,FALSE),"") -> 211 | H6: =IFERROR(VLOOKUP(B6,双一流!$B$2:$D$148,3,FALSE),"") -> 双一流 | I6: =IFERROR(VLOOKUP(B6,汇总!$B$2:$I$2921,8,FALSE),"") -> 理工 | J6: 本科 | K6: 公办
A7: 6 | B7: 北京航空航天大学 | C7: =VLOOKUP(B7,教育部大学名单!$B$1:$D$2920,3,FALSE) -> 工业和信息化部 | D7: 北京 | E7: 北京 | F7: =IFERROR(VLOOKUP(B7,'985'!$B$2:$D$40,3,FALSE),"") -> 985 | G7: =IFERROR(VLOOKUP(B7,'211'!$B$2:$D$116,3,FALSE),"") -> 211 | H7: =IFERROR(VLOOKUP(B7,双一流!$B$2:$D$148,3,FALSE),"") -> 双一流 | I7: =IFERROR(VLOOKUP(B7,汇总!$B$2:$I$2921,8,FALSE),"") -> 理工 | J7: 本科 | K7: 公办
A8: 7 | B8: 北京理工大学 | C8: =VLOOKUP(B8,教育部大学名单!$B$1:$D$2920,3,FALSE) -> 工业和信息化部 | D8: 北京 | E8: 北京 | F8: =IFERROR(VLOOKUP(B8,'985'!$B$2:$D$40,3,FALSE),"") -> 985 | G8: =IFERROR(VLOOKUP(B8,'211'!$B$2:$D$116,3,FALSE),"") -> 211 | H8: =IFERROR(VLOOKUP(B8,双一流!$B$2:$D$148,3,FALSE),"") -> 双一流 | I8: =IFERROR(VLOOKUP(B8,汇总!$B$2:$I$2921,8,FALSE),"") -> 理工 | J8: 本科 | K8: 公办
A9: 8 | B9: 北京科技大学 | C9: =VLOOKUP(B9,教育部大学名单!$B$1:$D$2920,3,FALSE) -> 教育部 | D9: 北京 | E9: 北京 | F9: =IFERROR(VLOOKUP(B9,'985'!$B$2:$D$40,3,FALSE),"") | G9: =IFERROR(VLOOKUP(B9,'211'!$B$2:$D$116,3,FALSE),"") -> 211 | H9: =IFERROR(VLOOKUP(B9,双一流!$B$2:$D$148,3,FALSE),"") -> 双一流 | I9: =IFERROR(VLOOKUP(B9,汇总!$B$2:$I$2921,8,FALSE),"") -> 理工 | J9: 本科 | K9: 公办
A10: 9 | B10: 北方工业大学 | C10: =VLOOKUP(B10,教育部大学名单!$B$1:$D$2920,3,FALSE) -> 北京市 | D10: 北京 | E10: 北京 | F10: =IFERROR(VLOOKUP(B10,'985'!$B$2:$D$40,3,FALSE),"") | G10: =IFERROR(VLOOKUP(B10,'211'!$B$2:$D$116,3,FALSE),"") | H10: =IFERROR(VLOOKUP(B10,双一流!$B$2:$D$148,3,FALSE),"") | I10: =IFERROR(VLOOKUP(B10,汇总!$B$2:$I$2921,8,FALSE),"") -> 理工 | J10: 本科 | K10: 公办
A11: 10 | B11: 北京化工大学 | C11: =VLOOKUP(B11,教育部大学名单!$B$1:$D$2920,3,FALSE) -> 教育部 | D11: 北京 | E11: 北京 | F11: =IFERROR(VLOOKUP(B11,'985'!$B$2:$D$40,3,FALSE),"") | G11: =IFERROR(VLOOKUP(B11,'211'!$B$2:$D$116,3,FALSE),"") -> 211 | H11: =IFERROR(VLOOKUP(B11,双一流!$B$2:$D$148,3,FALSE),"") -> 双一流 | I11: =IFERROR(VLOOKUP(B11,汇总!$B$2:$I$2921,8,FALSE),"") -> 理工 | J11: 本科 | K11: 公办
A12: 11 | B12: 北京工商大学 | C12: =VLOOKUP(B12,教育部大学名单!$B$1:$D$2920,3,FALSE) -> 北京市 | D12: 北京 | E12: 北京 | F12: =IFERROR(VLOOKUP(B12,'985'!$B$2:$D$40,3,FALSE),"") | G12: =IFERROR(VLOOKUP(B12,'211'!$B$2:$D$116,3,FALSE),"") | H12: =IFERROR(VLOOKUP(B12,双一流!$B$2:$D$148,3,FALSE),"") | I12: =IFERROR(VLOOKUP(B12,汇总!$B$2:$I$2921,8,FALSE),"") -> 财经 | J12: 本科 | K12: 公办
A13: 12 | B13: 北京服装学院 | C13: =VLOOKUP(B13,教育部大学名单!$B$1:$D$2920,3,FALSE) -> 北京市 | D13: 北京 | E13: 北京 | F13: =IFERROR(VLOOKUP(B13,'985'!$B$2:$D$40,3,FALSE),"") | G13: =IFERROR(VLOOKUP(B13,'211'!$B$2:$D$116,3,FALSE),"") | H13: =IFERROR(VLOOKUP(B13,双一流!$B$2:$D$148,3,FALSE),"") | I13: =IFERROR(VLOOKUP(B13,汇总!$B$2:$I$2921,8,FALSE),"") -> 艺术 | J13: 本科 | K13: 公办
... A2491: 2490 | B2491: 双河职业技术学院 | C2491: =VLOOKUP(B2491,教育部大学名单!$B$1:$D$2920,3,FALSE) -> 新疆生产建设兵团 | D2491: 新疆 | E2491: 双河 | F2491: =IFERROR(VLOOKUP(B2491,'985'!$B$2:$D$40,3,FALSE),"") | G2491: =IFERROR(VLOOKUP(B2491,'211'!$B$2:$D$116,3,FALSE),"") | H2491: =IFERROR(VLOOKUP(B2491,双一流!$B$2:$D$148,3,FALSE),"") | I2491: =IFERROR(VLOOKUP(B2491,汇总!$B$2:$I$2921,8,FALSE),"") -> 0 | J2491: 专科 | K2491: 公办
A2492: 2491 | B2492: 江西电子信息职业技术学院 | C2492: =VLOOKUP(B2492,教育部大学名单!$B$1:$D$2920,3,FALSE) -> 江西省 | D2492: 江西 | F2492: =IFERROR(VLOOKUP(B2492,'985'!$B$2:$D$40,3,FALSE),"") | G2492: =IFERROR(VLOOKUP(B2492,'211'!$B$2:$D$116,3,FALSE),"") | H2492: =IFERROR(VLOOKUP(B2492,双一流!$B$2:$D$148,3,FALSE),"") | I2492: =IFERROR(VLOOKUP(B2492,汇总!$B$2:$I$2921,8,FALSE),"") | J2492: 专科 | K2492: 公办
A2493: 2492 | B2493: 四平现代职业学院 | C2493: =VLOOKUP(B2493,教育部大学名单!$B$1:$D$2920,3,FALSE) -> 吉林省 | D2493: 吉林 | E2493: 四平 | F2493: =IFERROR(VLOOKUP(B2493,'985'!$B$2:$D$40,3,FALSE),"") | G2493: =IFERROR(VLOOKUP(B2493,'211'!$B$2:$D$116,3,FALSE),"") | H2493: =IFERROR(VLOOKUP(B2493,双一流!$B$2:$D$148,3,FALSE),"") | I2493: =IFERROR(VLOOKUP(B2493,汇总!$B$2:$I$2921,8,FALSE),"") | J2493: 专科 | K2493: 公办
A2494: 2493 | B2494: 常州铁道职业技术学院 | C2494: =VLOOKUP(B2494,教育部大学名单!$B$1:$D$2920,3,FALSE) -> 江苏省 | D2494: 江苏 | E2494: 常州 | F2494: =IFERROR(VLOOKUP(B2494,'985'!$B$2:$D$40,3,FALSE),"") | G2494: =IFERROR(VLOOKUP(B2494,'211'!$B$2:$D$116,3,FALSE),"") | H2494: =IFERROR(VLOOKUP(B2494,双一流!$B$2:$D$148,3,FALSE),"") | I2494: =IFERROR(VLOOKUP(B2494,汇总!$B$2:$I$2921,8,FALSE),"") | J2494: 专科 | K2494: 公办
A2495: 2494 | B2495: 苏州旅游职业学院 | C2495: =VLOOKUP(B2495,教育部大学名单!$B$1:$D$2920,3,FALSE) -> 江苏省 | D2495: 江苏 | E2495: 苏州 | F2495: =IFERROR(VLOOKUP(B2495,'985'!$B$2:$D$40,3,FALSE),"") | G2495: =IFERROR(VLOOKUP(B2495,'211'!$B$2:$D$116,3,FALSE),"") | H2495: =IFERROR(VLOOKUP(B2495,双一流!$B$2:$D$148,3,FALSE),"") | I2495: =IFERROR(VLOOKUP(B2495,汇总!$B$2:$I$2921,8,FALSE),"") | J2495: 专科 | K2495: 公办
A2496: 2495 | B2496: 南通卫生健康职业学院 | C2496: =VLOOKUP(B2496,教育部大学名单!$B$1:$D$2920,3,FALSE) -> 江苏省 | D2496: 江苏 | E2496: 南通 | F2496: =IFERROR(VLOOKUP(B2496,'985'!$B$2:$D$40,3,FALSE),"") | G2496: =IFERROR(VLOOKUP(B2496,'211'!$B$2:$D$116,3,FALSE),"") | H2496: =IFERROR(VLOOKUP(B2496,双一流!$B$2:$D$148,3,FALSE),"") | I2496: =IFERROR(VLOOKUP(B2496,汇总!$B$2:$I$2921,8,FALSE),"") | J2496: 专科 | K2496: 公办
A2497: 2496 | B2497: 六安应用科技职业学院 | C2497: =VLOOKUP(B2497,教育部大学名单!$B$1:$D$2920,3,FALSE) -> 安徽省 | D2497: 安徽 | E2497: 六安 | F2497: =IFERROR(VLOOKUP(B2497,'985'!$B$2:$D$40,3,FALSE),"") | G2497: =IFERROR(VLOOKUP(B2497,'211'!$B$2:$D$116,3,FALSE),"") | H2497: =IFERROR(VLOOKUP(B2497,双一流!$B$2:$D$148,3,FALSE),"") | I2497: =IFERROR(VLOOKUP(B2497,汇总!$B$2:$I$2921,8,FALSE),"") | J2497: 专科 | K2497: 公办
A2498: 2497 | B2498: 集美工业职业学院 | C2498: =VLOOKUP(B2498,教育部大学名单!$B$1:$D$2920,3,FALSE) -> 福建省 | D2498: 福建 | E2498: 厦门 | F2498: =IFERROR(VLOOKUP(B2498,'985'!$B$2:$D$40,3,FALSE),"") | G2498: =IFERROR(VLOOKUP(B2498,'211'!$B$2:$D$116,3,FALSE),"") | H2498: =IFERROR(VLOOKUP(B2498,双一流!$B$2:$D$148,3,FALSE),"") | I2498: =IFERROR(VLOOKUP(B2498,汇总!$B$2:$I$2921,8,FALSE),"") | J2498: 专科 | K2498: 公办
A2499: 2498 | B2499: 九江卫生健康职业学院 | C2499: =VLOOKUP(B2499,教育部大学名单!$B$1:$D$2920,3,FALSE) -> 江西省 | D2499: 江西 | E2499: 九江 | F2499: =IFERROR(VLOOKUP(B2499,'985'!$B$2:$D$40,3,FALSE),"") | G2499: =IFERROR(VLOOKUP(B2499,'211'!$B$2:$D$116,3,FALSE),"") | H2499: =IFERROR(VLOOKUP(B2499,双一流!$B$2:$D$148,3,FALSE),"") | I2499: =IFERROR(VLOOKUP(B2499,汇总!$B$2:$I$2921,8,FALSE),"") | J2499: 专科 | K2499: 公办
A2500: 2499 | B2500: 新余职业技术学院 | C2500: =VLOOKUP(B2500,教育部大学名单!$B$1:$D$2920,3,FALSE) -> 江西省 | D2500: 江西 | E2500: 新余 | F2500: =IFERROR(VLOOKUP(B2500,'985'!$B$2:$D$40,3,FALSE),"") | G2500: =IFERROR(VLOOKUP(B2500,'211'!$B$2:$D$116,3,FALSE),"") | H2500: =IFERROR(VLOOKUP(B2500,双一流!$B$2:$D$148,3,FALSE),"") | I2500: =IFERROR(VLOOKUP(B2500,汇总!$B$2:$I$2921,8,FALSE),"") | J2500: 专科 | K2500: 公办
A2501: 2500 | B2501: 聊城科技职业学院 | C2501: =VLOOKUP(B2501,教育部大学名单!$B$1:$D$2920,3,FALSE) -> 山东省 | D2501: 山东 | E2501: 聊城 | F2501: =IFERROR(VLOOKUP(B2501,'985'!$B$2:$D$40,3,FALSE),"") | G2501: =IFERROR(VLOOKUP(B2501,'211'!$B$2:$D$116,3,FALSE),"") | H2501: =IFERROR(VLOOKUP(B2501,双一流!$B$2:$D$148,3,FALSE),"") | I2501: =IFERROR(VLOOKUP(B2501,汇总!$B$2:$I$2921,8,FALSE),"") | J2501: 专科 | K2501: 公办
A2502: 2501 | B2502: 重庆农业职业学院 | C2502: =VLOOKUP(B2502,教育部大学名单!$B$1:$D$2920,3,FALSE) -> 重庆市 | D2502: 重庆 | E2502: 重庆 | F2502: =IFERROR(VLOOKUP(B2502,'985'!$B$2:$D$40,3,FALSE),"") | G2502: =IFERROR(VLOOKUP(B2502,'211'!$B$2:$D$116,3,FALSE),"") | H2502: =IFERROR(VLOOKUP(B2502,双一流!$B$2:$D$148,3,FALSE),"") | I2502: =IFERROR(VLOOKUP(B2502,汇总!$B$2:$I$2921,8,FALSE),"") | J2502: 专科 | K2502: 公办
A2503: 2502 | B2503: 宜宾工业职业技术学院 | C2503: =VLOOKUP(B2503,教育部大学名单!$B$1:$D$2920,3,FALSE) -> 四川省 | D2503: 四川 | E2503: 宜宾 | F2503: =IFERROR(VLOOKUP(B2503,'985'!$B$2:$D$40,3,FALSE),"") | G2503: =IFERROR(VLOOKUP(B2503,'211'!$B$2:$D$116,3,FALSE),"") | H2503: =IFERROR(VLOOKUP(B2503,双一流!$B$2:$D$148,3,FALSE),"") | I2503: =IFERROR(VLOOKUP(B2503,汇总!$B$2:$I$2921,8,FALSE),"") | J2503: 专科 | K2503: 公办
A2504: 2503 | B2504: 宜宾医药健康职业学院 | C2504: =VLOOKUP(B2504,教育部大学名单!$B$1:$D$2920,3,FALSE) -> 四川省 | D2504: 四川 | E2504: 宜宾 | F2504: =IFERROR(VLOOKUP(B2504,'985'!$B$2:$D$40,3,FALSE),"") | G2504: =IFERROR(VLOOKUP(B2504,'211'!$B$2:$D$116,3,FALSE),"") | H2504: =IFERROR(VLOOKUP(B2504,双一流!$B$2:$D$148,3,FALSE),"") | I2504: =IFERROR(VLOOKUP(B2504,汇总!$B$2:$I$2921,8,FALSE),"") | J2504: 专科 | K2504: 公办
... A2918: 2917 | B2918: 郑州亚欧交通职业学院 | C2918: =VLOOKUP(B2918,教育部大学名单!$B$1:$D$2920,3,FALSE) -> 河南省教育厅 | D2918: 河南 | E2918: 郑州 | F2918: =IFERROR(VLOOKUP(B2918,'985'!$B$2:$D$40,3,FALSE),"") | G2918: =IFERROR(VLOOKUP(B2918,'211'!$B$2:$D$116,3,FALSE),"") | H2918: =IFERROR(VLOOKUP(B2918,双一流!$B$2:$D$148,3,FALSE),"") | I2918: =IFERROR(VLOOKUP(B2918,汇总!$B$2:$I$2921,8,FALSE),"") -> 0 | J2918: 专科 | K2918: 中外合作办学

Sheet 教育部大学名单
A1: 序号 | B1: 学校名称 | C1: 学校标识码 | D1: 主管部门 | E1: 所在地 | F1: 办学层次 | G1: 备注
A2: 1 | B2: 北京大学 | C2: 4111010001 | D2: 教育部 | E2: 北京市 | F2: 本科
A3: 2 | B3: 中国人民大学 | C3: 4111010002 | D3: 教育部 | E3: 北京市 | F3: 本科
A4: 3 | B4: 清华大学 | C4: 4111010003 | D4: 教育部 | E4: 北京市 | F4: 本科
A5: 4 | B5: 北京交通大学 | C5: 4111010004 | D5: 教育部 | E5: 北京市 | F5: 本科
A6: 5 | B6: 北京工业大学 | C6: 4111010005 | D6: 北京市 | E6: 北京市 | F6: 本科
A7: 6 | B7: 北京航空航天大学 | C7: 4111010006 | D7: 工业和信息化部 | E7: 北京市 | F7: 本科
A8: 7 | B8: 北京理工大学 | C8: 4111010007 | D8: 工业和信息化部 | E8: 北京市 | F8: 本科
A9: 8 | B9: 北京科技大学 | C9: 4111010008 | D9: 教育部 | E9: 北京市 | F9: 本科
A10: 9 | B10: 北方工业大学 | C10: 4111010009 | D10: 北京市 | E10: 北京市 | F10: 本科
A11: 10 | B11: 北京化工大学 | C11: 4111010010 | D11: 教育部 | E11: 北京市 | F11: 本科
A12: 11 | B12: 北京工商大学 | C12: 4111010011 | D12: 北京市 | E12: 北京市 | F12: 本科
A13: 12 | B13: 北京服装学院 | C13: 4111010012 | D13: 北京市 | E13: 北京市 | F13: 本科
... A56: 55 | B56: 北京联合大学 | C56: 4111011417 | D56: 北京市 | E56: 北京市 | F56: 本科
A57: 56 | B57: 北京城市学院 | C57: 4111011418 | D57: 北京市教委 | E57: 北京市 | F57: 本科 | G57: 民办
A58: 57 | B58: 中国青年政治学院 | C58: 4111011625 | D58: 共青团中央 | E58: 北京市 | F58: 本科
A59: 58 | B59: 首钢工学院 | C59: 4111011831 | D59: 北京市 | E59: 北京市 | F59: 本科
A60: 59 | B60: 中国劳动关系学院 | C60: 4111012453 | D60: 中华全国总工会 | E60: 北京市 | F60: 本科
A61: 60 | B61: 首都师范大学科德学院 | C61: 4111013629 | D61: 北京市教委 | E61: 北京市 | F61: 本科 | G61: 民办
A62: 61 | B62: 北京金融科技学院 | C62: 4111013630 | D62: 北京市教委 | E62: 北京市 | F62: 本科 | G62: 民办
A63: 62 | B63: 北京邮电大学世纪学院 | C63: 4111013901 | D63: 北京市教委 | E63: 北京市 | F63: 本科 | G63: 民办
A64: 63 | B64: 北京工业大学耿丹学院 | C64: 4111013904 | D64: 北京市教委 | E64: 北京市 | F64: 本科 | G64: 民办
A65: 64 | B65: 北京警察学院 | C65: 4111014019 | D65: 北京市 | E65: 北京市 | F65: 本科
A66: 65 | B66: 北京第二外国语学院中瑞酒店管理学院 | C66: 4111014201 | D66: 北京市教委 | E66: 北京市 | F66: 本科 | G66: 民办
A67: 66 | B67: 中国科学院大学 | C67: 4111014430 | D67: 中国科学院 | E67: 北京市 | F67: 本科
A68: 67 | B68: 中国社会科学院大学 | C68: 4111014596 | D68: 中国社会科学院 | E68: 北京市 | F68: 本科
A69: 68 | B69: 民政职业大学 | C69: 4111014139 | D69: 民政部 | E69: 北京市 | F69: 本科
A70: 69 | B70: 北京科技职业大学 | C70: 4111010858 | D70: 北京市 | E70: 北京市 | F70: 本科
A71: 70 | B71: 北京工业职业技术学院 | C71: 4111010853 | D71: 北京市 | E71: 北京市 | F71: 专科
A72: 71 | B72: 北京信息职业技术学院 | C72: 4111010857 | D72: 北京市 | E72: 北京市 | F72: 专科
A73: 72 | B73: 北京京北职业技术学院 | C73: 4111011090 | D73: 北京市 | E73: 北京市 | F73: 专科
A74: 73 | B74: 北京交通职业技术学院 | C74: 4111011092 | D74: 北京市 | E74: 北京市 | F74: 专科
A75: 74 | B75: 北京青年政治学院 | C75: 4111011626 | D75: 北京市 | E75: 北京市 | F75: 专科
A76: 75 | B76: 北京农业职业学院 | C76: 4111012448 | D76: 北京市 | E76: 北京市 | F76: 专科
A77: 76 | B77: 北京政法职业学院 | C77: 4111012451 | D77: 北京市 | E77: 北京市 | F77: 专科
A78: 77 | B78: 北京财贸职业学院 | C78: 4111012561 | D78: 北京市 | E78: 北京市 | F78: 专科
A79: 78 | B79: 北京北大方正软件职业技术学院 | C79: 4111012564 | D79: 北京市教委 | E79: 北京市 | F79: 专科 | G79: 民办
A80: 79 | B80: 北京经贸职业学院 | C80: 4111012565 | D80: 北京市教委 | E80: 北京市 | F80: 专科 | G80: 民办
A81: 80 | B81: 北京经济技术职业学院 | C81: 4111012566 | D81: 北京市教委 | E81: 北京市 | F81: 专科 | G81: 民办
A82: 81 | B82: 北京戏曲艺术职业学院 | C82: 4111012567 | D82: 北京市 | E82: 北京市 | F82: 专科
...

Sheet 汇总
A1: 序号 | B1: 学校名称 | C1: 主管部门 | D1: 省份 | E1: 城市 | F1: 985 | G1: 211 | H1: 双一流 | I1: 类型 | J1: 层次 | K1: 性质
A2: 1 | B2: 北京大学 | C2: 教育部 | D2: 北京 | E2: 北京 | F2: 985 | G2: 211 | H2: 双一流 | I2: 综合 | J2: 本科 | K2: 公办
A3: 2 | B3: 中国人民大学 | C3: 教育部 | D3: 北京 | E3: 北京 | F3: 985 | G3: 211 | H3: 双一流 | I3: 综合 | J3: 本科 | K3: 公办
A4: 3 | B4: 清华大学 | C4: 教育部 | D4: 北京 | E4: 北京 | F4: 985 | G4: 211 | H4: 双一流 | I4: 综合 | J4: 本科 | K4: 公办
A5: 4 | B5: 北京交通大学 | C5: 教育部 | D5: 北京 | E5: 北京 | G5: 211 | H5: 双一流 | I5: 理工 | J5: 本科 | K5: 公办
A6: 5 | B6: 北京工业大学 | C6: 北京市 | D6: 北京 | E6: 北京 | G6: 211 | H6: 双一流 | I6: 理工 | J6: 本科 | K6: 公办
A7: 6 | B7: 北京航空航天大学 | C7: 工业和信息化部 | D7: 北京 | E7: 北京 | F7: 985 | G7: 211 | H7: 双一流 | I7: 理工 | J7: 本科 | K7: 公办
A8: 7 | B8: 北京理工大学 | C8: 工业和信息化部 | D8: 北京 | E8: 北京 | F8: 985 | G8: 211 | H8: 双一流 | I8: 理工 | J8: 本科 | K8: 公办
A9: 8 | B9: 北京科技大学 | C9: 教育部 | D9: 北京 | E9: 北京 | G9: 211 | H9: 双一流 | I9: 理工 | J9: 本科 | K9: 公办
A10: 9 | B10: 北方工业大学 | C10: 北京市 | D10: 北京 | E10: 北京 | I10: 理工 | J10: 本科 | K10: 公办
A11: 10 | B11: 北京化工大学 | C11: 教育部 | D11: 北京 | E11: 北京 | G11: 211 | H11: 双一流 | I11: 理工 | J11: 本科 | K11: 公办
A12: 11 | B12: 北京工商大学 | C12: 北京市 | D12: 北京 | E12: 北京 | I12: 财经 | J12: 本科 | K12: 公办
A13: 12 | B13: 北京服装学院 | C13: 北京市 | D13: 北京 | E13: 北京 | I13: 艺术 | J13: 本科 | K13: 公办
A14: 13 | B14: 北京邮电大学 | C14: 教育部 | D14: 北京 | E14: 北京 | G14: 211 | H14: 双一流 | I14: 理工 | J14: 本科 | K14: 公办
A15: 14 | B15: 北京印刷学院 | C15: 北京市 | D15: 北京 | E15: 北京 | I15: 理工 | J15: 本科 | K15: 公办
A16: 15 | B16: 北京建筑大学 | C16: 北京市 | D16: 北京 | E16: 北京 | I16: 理工 | J16: 本科 | K16: 公办
A17: 16 | B17: 北京石油化工学院 | C17: 北京市 | D17: 北京 | E17: 北京 | J17: 本科 | K17: 公办
A18: 17 | B18: 北京电子科技学院 | C18: 中央办公厅 | D18: 北京 | E18: 北京 | I18: 理工 | J18: 本科 | K18: 公办
A19: 18 | B19: 中国农业大学 | C19: 教育部 | D19: 北京 | E19: 北京 | F19: 985 | G19: 211 | H19: 双一流 | I19: 农林 | J19: 本科 | K19: 公办
A20: 19 | B20: 北京农学院 | C20: 北京市 | D20: 北京 | E20: 北京 | J20: 本科 | K20: 公办
A21: 20 | B21: 北京林业大学 | C21: 教育部 | D21: 北京 | E21: 北京 | G21: 211 | H21: 双一流 | I21: 农林 | J21: 本科 | K21: 公办
A22: 21 | B22: 北京协和医学院 | C22: 国家卫生健康委员会 | D22: 北京 | E22: 北京 | H22: 是 | I22: 医药 | J22: 本科 | K22: 公办
A23: 22 | B23: 首都医科大学 | C23: 北京市 | D23: 北京 | E23: 北京 | I23: 医药 | J23: 本科 | K23: 公办
A24: 23 | B24: 北京中医药大学 | C24: 教育部 | D24: 北京 | E24: 北京 | G24: 211 | H24: 双一流 | I24: 医药 | J24: 本科 | K24: 公办
A25: 24 | B25: 北京师范大学 | C25: 教育部 | D25: 北京 | E25: 北京 | F25: 985 | G25: 211 | H25: 双一流 | I25: 师范 | J25: 本科 | K25: 公办
A26: 25 | B26: 首都师范大学 | C26: 北京市 | D26: 北京 | E26: 北京 | H26: 是 | I26: 师范 | J26: 本科 | K26: 公办
A27: 26 | B27: 首都体育学院 | C27: 北京市 | D27: 北京 | E27: 北京 | I27: 体育 | J27: 本科 | K27: 公办
A28: 27 | B28: 北京外国语大学 | C28: 教育部 | D28: 北京 | E28: 北京 | G28: 211 | H28: 双一流 | I28: 语言 | J28: 本科 | K28: 公办
A29: 28 | B29: 北京第二外国语学院 | C29: 北京市 | D29: 北京 | E29: 北京 | I29: 语言 | J29: 本科 | K29: 公办
A30: 29 | B30: 北京语言大学 | C30: 教育部 | D30: 北京 | E30: 北京 | I30: 语言 | J30: 本科 | K30: 公办
A31: 30 | B31: 中国传媒大学 | C31: 教育部 | D31: 北京 | E31: 北京 | G31: 211 | H31: 双一流 | I31: 综合 | J31: 本科 | K31: 公办
A32: 31 | B32: 中央财经大学 | C32: 教育部 | D32: 北京 | E32: 北京 | G32: 211 | H32: 双一流 | I32: 财经 | J32: 本科 | K32: 公办
A33: 32 | B33: 对外经济贸易大学 | C33: 教育部 | D33: 北京 | E33: 北京 | G33: 211 | H33: 双一流 | I33: 财经 | J33: 本科 | K33: 公办
A34: 33 | B34: 北京物资学院 | C34: 北京市 | D34: 北京 | E34: 北京 | I34: 财经 | J34: 本科 | K34: 公办
A35: 34 | B35: 首都经济贸易大学 | C35: 北京市 | D35: 北京 | E35: 北京 | I35: 财经 | J35: 本科 | K35: 公办
A36: 35 | B36: 中国消防救援学院 | C36: 应急管理部 | D36: 北京 | E36: 北京 | J36: 本科 | K36: 公办
A37: 36 | B37: 外交学院 | C37: 外交部 | D37: 北京 | E37: 北京 | H37: 是 | I37: 语言 | J37: 本科 | K37: 公办
A38: 37 | B38: 中国人民公安大学 | C38: 公安部 | D38: 北京 | E38: 北京 | H38: 是 | I38: 政法 | J38: 本科 | K38: 公办
A39: 38 | B39: 国际关系学院 | C39: 教育部 | D39: 北京 | E39: 北京 | I39: 政法 | J39: 本科 | K39: 公办
A40: 39 | B40: 北京体育大学 | C40: 国家体育总局 | D40: 北京 | E40: 北京 | G40: 211 | H40: 双一流 | I40: 体育 | J40: 本科 | K40: 公办
...

Sheet 本科
A1: 序号 | B1: 学校名称 | C1: 省份 | D1: 城市 | E1: 层次 | F1: 备注
A2: 1 | B2: 北京大学 | C2: 北京 | D2: 北京 | E2: 本科 | F2: 公办
A3: 2 | B3: 中国人民大学 | C3: 北京 | D3: 北京 | E3: 本科 | F3: 公办
A4: 3 | B4: 清华大学 | C4: 北京 | D4: 北京 | E4: 本科 | F4: 公办
A5: 4 | B5: 北京交通大学 | C5: 北京 | D5: 北京 | E5: 本科 | F5: 公办
A6: 5 | B6: 北京工业大学 | C6: 北京 | D6: 北京 | E6: 本科 | F6: 公办
A7: 6 | B7: 北京航空航天大学 | C7: 北京 | D7: 北京 | E7: 本科 | F7: 公办
A8: 7 | B8: 北京理工大学 | C8: 北京 | D8: 北京 | E8: 本科 | F8: 公办
A9: 8 | B9: 北京科技大学 | C9: 北京 | D9: 北京 | E9: 本科 | F9: 公办
A10: 9 | B10: 北方工业大学 | C10: 北京 | D10: 北京 | E10: 本科 | F10: 公办
A11: 10 | B11: 北京化工大学 | C11: 北京 | D11: 北京 | E11: 本科 | F11: 公办
A12: 11 | B12: 北京工商大学 | C12: 北京 | D12: 北京 | E12: 本科 | F12: 公办
A13: 12 | B13: 北京服装学院 | C13: 北京 | D13: 北京 | E13: 本科 | F13: 公办
... A2491: 2490 | B2491: 双河职业技术学院 | C2491: 新疆 | D2491: 双河 | E2491: 专科 | F2491: 公办
A2492: 2491 | B2492: 江西电子信息职业技术学院 | C2492: 江西 | E2492: 专科 | F2492: 公办
A2493: 2492 | B2493: 四平现代职业学院 | C2493: 吉林 | D2493: 四平 | E2493: 专科 | F2493: 公办
A2494: 2493 | B2494: 常州铁道职业技术学院 | C2494: 江苏 | D2494: 常州 | E2494: 专科 | F2494: 公办
A2495: 2494 | B2495: 苏州旅游职业学院 | C2495: 江苏 | D2495: 苏州 | E2495: 专科 | F2495: 公办
A2496: 2495 | B2496: 南通卫生健康职业学院 | C2496: 江苏 | D2496: 南通 | E2496: 专科 | F2496: 公办
A2497: 2496 | B2497: 六安应用科技职业学院 | C2497: 安徽 | D2497: 六安 | E2497: 专科 | F2497: 公办
A2498: 2497 | B2498: 集美工业职业学院 | C2498: 福建 | D2498: 厦门 | E2498: 专科 | F2498: 公办
A2499: 2498 | B2499: 九江卫生健康职业学院 | C2499: 江西 | D2499: 九江 | E2499: 专科 | F2499: 公办
A2500: 2499 | B2500: 新余职业技术学院 | C2500: 江西 | D2500: 新余 | E2500: 专科 | F2500: 公办
A2501: 2500 | B2501: 聊城科技职业学院 | C2501: 山东 | D2501: 聊城 | E2501: 专科 | F2501: 公办
A2502: 2501 | B2502: 重庆农业职业学院 | C2502: 重庆 | D2502: 重庆 | E2502: 专科 | F2502: 公办
A2503: 2502 | B2503: 宜宾工业职业技术学院 | C2503: 四川 | D2503: 宜宾 | E2503: 专科 | F2503: 公办
A2504: 2503 | B2504: 宜宾医药健康职业学院 | C2504: 四川 | D2504: 宜宾 | E2504: 专科 | F2504: 公办
... A2918: 2917 | B2918: 郑州亚欧交通职业学院 | C2918: 河南 | D2918: 郑州 | E2918: 专科 | F2918: 中外合作办学

Sheet 专科
A1: 序号 | B1: 学校名称 | C1: 省份 | D1: 城市 | E1: 层次 | F1: 备注
A2: 1 | B2: 北京工业职业技术学院 | C2: 北京 | D2: 北京 | E2: 专科 | F2: 公办
A3: 2 | B3: 北京信息职业技术学院 | C3: 北京 | D3: 北京 | E3: 专科 | F3: 公办
A4: 3 | B4: 北京京北职业技术学院 | C4: 北京 | D4: 北京 | E4: 专科 | F4: 公办
A5: 4 | B5: 北京交通职业技术学院 | C5: 北京 | D5: 北京 | E5: 专科 | F5: 公办
A6: 5 | B6: 北京青年政治学院 | C6: 北京 | D6: 北京 | E6: 专科 | F6: 公办
A7: 6 | B7: 北京农业职业学院 | C7: 北京 | D7: 北京 | E7: 专科 | F7: 公办
A8: 7 | B8: 北京政法职业学院 | C8: 北京 | D8: 北京 | E8: 专科 | F8: 公办
A9: 8 | B9: 北京财贸职业学院 | C9: 北京 | D9: 北京 | E9: 专科 | F9: 公办
A10: 9 | B10: 北京戏曲艺术职业学院 | C10: 北京 | D10: 北京 | E10: 专科 | F10: 公办
A11: 10 | B11: 北京经济管理职业学院 | C11: 北京 | D11: 北京 | E11: 专科 | F11: 公办
A12: 11 | B12: 北京劳动保障职业学院 | C12: 北京 | D12: 北京 | E12: 专科 | F12: 公办
A13: 12 | B13: 北京体育职业学院 | C13: 北京 | D13: 北京 | E13: 专科 | F13: 公办
... A1112: 1111 | B1112: 双河职业技术学院 | C1112: 新疆 | D1112: 双河 | E1112: 专科 | F1112: 公办
A1113: 1112 | B1113: 江西电子信息职业技术学院 | C1113: 江西 | E1113: 专科 | F1113: 公办
A1114: 1113 | B1114: 四平现代职业学院 | C1114: 吉林 | D1114: 四平 | E1114: 专科 | F1114: 公办
A1115: 1114 | B1115: 常州铁道职业技术学院 | C1115: 江苏 | D1115: 常州 | E1115: 专科 | F1115: 公办
A1116: 1115 | B1116: 苏州旅游职业学院 | C1116: 江苏 | D1116: 苏州 | E1116: 专科 | F1116: 公办
A1117: 1116 | B1117: 南通卫生健康职业学院 | C1117: 江苏 | D1117: 南通 | E1117: 专科 | F1117: 公办
A1118: 1117 | B1118: 六安应用科技职业学院 | C1118: 安徽 | D1118: 六安 | E1118: 专科 | F1118: 公办
A1119: 1118 | B1119: 集美工业职业学院 | C1119: 福建 | D1119: 厦门 | E1119: 专科 | F1119: 公办
A1120: 1119 | B1120: 九江卫生健康职业学院 | C1120: 江西 | D1120: 九江 | E1120: 专科 | F1120: 公办
A1121: 1120 | B1121: 新余职业技术学院 | C1121: 江西 | D1121: 新余 | E1121: 专科 | F1121: 公办
A1122: 1121 | B1122: 聊城科技职业学院 | C1122: 山东 | D1122: 聊城 | E1122: 专科 | F1122: 公办
A1123: 1122 | B1123: 重庆农业职业学院 | C1123: 重庆 | D1123: 重庆 | E1123: 专科 | F1123: 公办
A1124: 1123 | B1124: 宜宾工业职业技术学院 | C1124: 四川 | D1124: 宜宾 | E1124: 专科 | F1124: 公办
A1125: 1124 | B1125: 宜宾医药健康职业学院 | C1125: 四川 | D1125: 宜宾 | E1125: 专科 | F1125: 公办
... A1539: 1538 | B1539: 郑州亚欧交通职业学院 | C1539: 河南 | D1539: 郑州 | E1539: 专科 | F1539: 中外合作办学

Sheet 985
A1: 排名 | B1: 名称 | C1: 所在地 | D1: 985
A2: 1 | B2: 清华大学 | C2: 北京 | D2: 985
A3: 2 | B3: 北京大学 | C3: 北京 | D3: 985
A4: 3 | B4: 中国科学技术大学 | C4: 安徽 | D4: 985
A5: 4 | B5: 复旦大学 | C5: 上海 | D5: 985
A6: 5 | B6: 中国人民大学 | C6: 北京 | D6: 985
A7: 6 | B7: 上海交通大学 | C7: 上海 | D7: 985
A8: 7 | B8: 南京大学 | C8: 江苏 | D8: 985
A9: 8 | B9: 同济大学 | C9: 上海 | D9: 985
A10: 9 | B10: 浙江大学 | C10: 浙江 | D10: 985
A11: 10 | B11: 南开大学 | C11: 天津 | D11: 985
A12: 11 | B12: 北京航空航天大学 | C12: 北京 | D12: 985
A13: 12 | B13: 北京师范大学 | C13: 北京 | D13: 985
... A39: 38 | B39: 西北农林科技大学 | C39: 陕西 | D39: 985
A40: 暂无 | B40: 国防科技大学 | C40: 湖南 | D40: 985

Sheet 211
A1: 序号 | B1: 名称 | C1: 所在地 | D1: 211
A2: 1 | B2: 中国科学技术大学 | C2: 安徽 | D2: 211
A3: 2 | B3: 合肥工业大学 | C3: 安徽 | D3: 211
A4: 3 | B4: 安徽大学 | C4: 安徽 | D4: 211
A5: 4 | B5: 清华大学 | C5: 北京 | D5: 211
A6: 5 | B6: 北京大学 | C6: 北京 | D6: 211
A7: 6 | B7: 中国人民大学 | C7: 北京 | D7: 211
A8: 7 | B8: 北京航空航天大学 | C8: 北京 | D8: 211
A9: 8 | B9: 中央财经大学 | C9: 北京 | D9: 211
A10: 9 | B10: 北京师范大学 | C10: 北京 | D10: 211
A11: 10 | B11: 对外经济贸易大学 | C11: 北京 | D11: 211
A12: 11 | B12: 北京理工大学 | C12: 北京 | D12: 211
A13: 12 | B13: 北京外国语大学 | C13: 北京 | D13: 211
... A116: 115 | B116: 西南大学 | C116: 重庆 | D116: 211

Sheet 双一流
A1: 序号 | B1: 学校名称 | C1: 3232 | D1: 双一流
A2: 1 | B2: 北京大学 | D2: 双一流
A3: 2 | B3: 中国人民大学 | D3: 双一流
A4: 3 | B4: 清华大学 | D4: 双一流
A5: 4 | B5: 北京交通大学 | D5: 双一流
A6: 5 | B6: 北京工业大学 | D6: 双一流
A7: 6 | B7: 北京航空航天大学 | D7: 双一流
A8: 7 | B8: 北京理工大学 | D8: 双一流
A9: 8 | B9: 北京科技大学 | D9: 双一流
A10: 9 | B10: 北京化工大学 | D10: 双一流
A11: 10 | B11: 北京邮电大学 | D11: 双一流
A12: 11 | B12: 中国农业大学 | D12: 双一流
A13: 12 | B13: 北京林业大学 | D13: 双一流
... A148: 147 | B148: 空军军医大学 | D148: 双一流

Sheet 公式
A1: 汇总
A2: 序号 | B2: 学校名称 | C2: 主管部门 | D2: 省份 | E2: 城市 | F2: 985 | G2: 211 | H2: 双一流 | I2: 类型 | J2: 层次 | K2: 性质
A3: 1 | B3: 北京大学 | C3: {=VLOOKUP(寻找的值,所在的表,2,0)} -> #NAME? | D3: {=VLOOKUP(寻找的值,所在的表,3,0)} -> #NAME? | E3: =VLOOKUP(寻找的值,所在的表,4,0) -> #NAME? | F3: {=VLOOKUP(寻找的值,所在的表,5,0)} -> #NAME? | G3: {=VLOOKUP(寻找的值,所在的表,6,0)} -> #NAME? | H3: {=VLOOKUP(寻找的值,所在的表,7,0)} -> #NAME? | I3: {=VLOOKUP(寻找的值,所在的表,8,0)} -> #NAME? | J3: {=VLOOKUP(寻找的值,所在的表,9,0)} -> #NAME? | K3: {=VLOOKUP(寻找的值,所在的表,10,0)} -> #NAME?
B5: 学校名称 | C5: 专业组 | D5: 选科
A6: 获取左边 | B6: 陆军工程大学06专业组(不限) | C6: =LEFT(B6,FIND("(",B6)-1) -> 陆军工程大学06专业组 | D6: =MID(B6,FIND("(",B6),LEN(B6)-FIND("(",B6)+1) -> (不限)
